Workbook

Sheet FVA
A1: FONDO VALOR ACTIVO
A2: 45274
B4: FECHA | C4: DEPOSITO | D4: TOTAL | E4: UNID | F4: VOLUMEN | G4: GANANCIA | H4: RENTABILIDAD | J4: PRODUCTO | K4: DEPOSITO | L4: ACTIVO | M4: VARIACION | O4: INDICADORES
B5: {=INDIRECT("datos!a2:g22")} -> 13 | D5: 26552325 | E5: 1391.1308 | F5: 28747167 | G5: 3707.2705 | H5: 2272325 | J5: ACTIVO 1 | K5: =27*11680+51*11680+71*11480 -> 1726120 | L5: =SUMIF(CUENTAS!$1:$1,J5,CUENTAS!$2:$2) -> 2604140 | M5: =(L5-K5)/K5 -> 0.50866684 | O5: TIEMPO | P5: TASA | Q5: EA
B6: 14 | D6: 0.086859262 | E6: 0.079699031 | F6: 0.079849388 | G6: -0.26750041 | H6: 0.0016341539 | J6: ACTIVO 2 | K6: =1886815/38*12+33*54900 -> 2407536.3 | L6: =SUMIF(CUENTAS!$1:$1,J6,CUENTAS!$2:$2) -> 2470500 | M6: =(L6-K6)/K6 -> 0.026152745 | O6: =TODAY()-O7 -> 67 | P6: =(BALANCE!C10-GRAFICO!B77)/GRAFICO!B77 -> -0.004011439 | Q6: =(1+P6)^(365/O6)-1 -> -0.021659305
B7: 46098 | J7: ACTIVO 3 | K7: =6*70900 -> 425400 | L7: =SUMIF(CUENTAS!$1:$1,J7,CUENTAS!$2:$2) -> 373680 | M7: =(L7-abs(K7))/abs(K7) -> -0.12157969 | O7: 46023
B8: 46097 | J8: ACTIVO 4 | K8: =44081.18*80 -> 3526494.4 | L8: =SUMIF(CUENTAS!$1:$1,J8,CUENTAS!$2:$2) -> 3328000 | M8: =(L8-K8)/K8 -> -0.056286606 | O8: INVERSION | P8: VALORIZACION | Q8: RENTABILIDAD
B9: 46096 | J9: ACTIVO 20 | K9: 283000 | L9: =SUMIF(CUENTAS!$1:$1,J9,CUENTAS!$2:$2) -> 283608 | M9: =(L9-K9)/K9 -> 0.0021484099 | O9: =DATOS!C2 -> 26552325 | P9: =DATOS!E2 -> 28747167 | Q9: =P9-O9 -> 2194842
B10: 46095 | J10: ACTIVO 6 | K10: =2*70000 -> 140000 | L10: =SUMIF(CUENTAS!$1:$1,J10,CUENTAS!$2:$2) -> 135000 | M10: =(L10-K10)/K10 -> -0.035714286 | O10: EFECTIVO | P10: ACTIVOS | Q10: COMISION
B11: 46094 | J11: ACTIVO 7 | K11: =59*17040 -> 1005360 | L11: =SUMIF(CUENTAS!$1:$1,J11,CUENTAS!$2:$2) -> 962880 | M11: =(L11-K11)/K11 -> -0.042253521 | O11: =SUMIF(J5:J26,"cartera",L5:L26) -> 3876499.8 | P11: =SUM(L5:L24) -> 37025616 | Q11: =Q9*7% -> 153638.94
B12: 46093 | J12: ACTIVO 8 | K12: =64*15520+60*18700 -> 2115280 | L12: =SUMIF(CUENTAS!$1:$1,J12,CUENTAS!$2:$2) -> 2351040 | M12: =(L12-K12)/K12 -> 0.11145569 | O12: =AVERAGE(CUENTAS!$AA$60:AA1388) -> 1019726.7
B13: 46092 | J13: ACTIVO 9 | K13: =552000-150000 -> 402000 | L13: =SUMIF(CUENTAS!$1:$1,J13,CUENTAS!$2:$2) -> 814000 | M13: =(L13-K13)/K13 -> 1.0248756
B14: 46091 | J14: ACTIVO 10 | K14: =654000+1573000 -> 2227000 | L14: =SUMIF(CUENTAS!$1:$1,J14,CUENTAS!$2:$2) -> 1090000 | M14: =(L14-K14)/K14 -> -0.51055231
B15: 46090 | J15: ACTIVO 11 | K15: =654000+1197400 -> 1851400 | L15: =SUMIF(CUENTAS!$1:$1,J15,CUENTAS!$2:$2) -> 1195525 | M15: =(L15-K15)/K15 -> -0.35425894
B16: 46089 | C16: 2122000 | D16: 26552325 | E16: 1391.1308 | F16: 28747167 | G16: 3707.2705 | H16: 2272325 | J16: ACTIVO 12 | K16: =815330+1524360+600000 -> 2939690 | L16: =SUMIF(CUENTAS!$1:$1,J16,CUENTAS!$2:$2) -> 1704253 | M16: =(L16-K16)/K16 -> -0.42026098
B17: 46088 | D17: 24430325 | E17: 1288.4431 | F17: 26621460 | G17: 5061.1229 | H17: 2268617.7 | J17: ACTIVO 13 | K17: =882000+112000+180000+180000+220000+220000+85000+220000 -> 2099000 | L17: =SUMIF(CUENTAS!$1:$1,J17,CUENTAS!$2:$2) -> 578622.2 | M17: =(L17-K17)/K17 -> -0.72433435
B18: 46087 | D18: 24430325 | E18: 1288.4431 | F18: 26616399 | G18: -62284.025 | H18: 2263556.6 | J18: ACTIVO 14 | K18: 1000000 | L18: =SUMIF(CUENTAS!$1:$1,J18,CUENTAS!$2:$2) -> 5071335 | M18: =(L18-K18)/K18 -> 4.071335
B19: 46086 | D19: 24430325 | E19: 1288.4431 | F19: 26678683 | G19: -6089.1721 | H19: 2325840.6 | J19: ACTIVO 15 | K19: 1300000 | L19: =SUMIF(CUENTAS!$1:$1,J19,CUENTAS!$2:$2) -> 1344990.1 | M19: =(L19-K19)/K19 -> 0.034607748
B20: 46085 | D20: 24430325 | E20: 1288.4431 | F20: 26684772 | G20: -3934.3195 | H20: 2331929.8 | J20: ACTIVO 16 | K20: =3005000 -> 3005000 | L20: =SUMIF(CUENTAS!$1:$1,J20,CUENTAS!$2:$2) -> 3649929.6 | M20: =(L20-K20)/K20 -> 0.21461884
B21: 46084 | C21: 110000 | D21: 24430325 | E21: 1288.4431 | F21: 26688706 | G21: -35866.467 | H21: 2335864.1 | J21: ACTIVO 17 | K21: =493*2305 -> 1136365 | L21: =SUMIF(CUENTAS!$1:$1,J21,CUENTAS!$2:$2) -> 1019085 | M21: =(L21-K21)/K21 -> -0.10320628
B22: 46083 | D22: 24320325 | E22: 1283.1327 | F22: 26614573 | G22: -567681.61 | H22: 2371730.5 | J22: ACTIVO 18 | K22: 865000 | L22: =SUMIF(CUENTAS!$1:$1,J22,CUENTAS!$2:$2) -> 1139540.2 | M22: =(L22-K22)/K22 -> 0.31738755
B23: 46082 | D23: 24320325 | E23: 1283.1327 | F23: 27182254 | G23: -10341.762 | H23: 2939412.2 | J23: ACTIVO 19 | K23: =230000*5 -> 1150000 | L23: =SUMIF(CUENTAS!$1:$1,J23,CUENTAS!$2:$2) -> 3032988.4 | M23: =(L23-K23)/K23 -> 1.6373812
B24: 46081 | D24: 24320325 | E24: 1283.1327 | F24: 27192596 | G24: -10341.909 | H24: 2949753.9 | J24: CARTERA | K24: 3876000 | L24: =SUMIF(CUENTAS!$1:$1,J24,CUENTAS!$2:$2) -> 3876499.8 | M24: =(L24-K24)/K24 -> 0.00012894737
B25: 46080 | D25: 24320325 | E25: 1283.1327 | F25: 27202938 | G25: -383792.06 | H25: 2960095.8 | J25: APALANCAMIENTO | K25: =-3450000-4000000 -> -7450000 | L25: =-SUMIF(CUENTAS!$1:$1,J25,CUENTAS!$2:$2) -> -8273161.2 | M25: =(L25-K25)/K25 -> 0.11049144
J26: GASTOS | L26: =SUMIF(CUENTAS!$1:$1,J26,CUENTAS!$2:$2) -> 5288.0822

Sheet DATOS
A1: FECHA | B1: DEPOSITO | C1: TOTAL | D1: UNIDADES | E1: VOLUMEN | F1: GANANCIA | G1: RENTABILIDAD
A2: =IFERROR(__xludf.DUMMYFUNCTION("MIN(FILTER(ROW($C$4:$C1385),MMULT(N(LEN($C$4:$G1385)>0), TRANSPOSE(COLUMN($C$4:$G$4)^0)) = COLUMNS($C$4:$G1385)))"),13.0) -> 13 | C2: =INDIRECT(ADDRESS($A$2, COLUMN())) -> 26552325 | D2: =INDIRECT(ADDRESS($A$2, COLUMN())) -> 1391.1308 | E2: =INDIRECT(ADDRESS($A$2, COLUMN())) -> 28747167 | F2: =INDIRECT(ADDRESS($A$2, COLUMN())) -> 3707.2705 | G2: =INDIRECT(ADDRESS($A$2, COLUMN())) -> 2272325
A3: =A2+1 -> 14 | C3: =(INDIRECT(ADDRESS($A$2, COLUMN()))-INDIRECT(ADDRESS($A$3, COLUMN())))/INDIRECT(ADDRESS($A$3, COLUMN())) -> 0.086859262 | D3: =(INDIRECT(ADDRESS($A$2, COLUMN()))-INDIRECT(ADDRESS($A$3, COLUMN())))/INDIRECT(ADDRESS($A$3, COLUMN())) -> 0.079699031 | E3: =(INDIRECT(ADDRESS($A$2, COLUMN()))-INDIRECT(ADDRESS($A$3, COLUMN())))/INDIRECT(ADDRESS($A$3, COLUMN())) -> 0.079849388 | F3: =(INDIRECT(ADDRESS($A$2, COLUMN()))-INDIRECT(ADDRESS($A$3, COLUMN())))/INDIRECT(ADDRESS($A$3, COLUMN())) -> -0.26750041 | G3: =(INDIRECT(ADDRESS($A$2, COLUMN()))-INDIRECT(ADDRESS($A$3, COLUMN())))/INDIRECT(ADDRESS($A$3, COLUMN())) -> 0.0016341539
A4: 46098 | C4: =IF(D4="","",C5+B4) | D4: =IF(E4="","",D5) | E4: =IFERROR(__xludf.DUMMYFUNCTION("FILTER(CUENTAS!AB:AB,A4=CUENTAS!A:A) "),"") | F4: =(IF(E4<>0,E4-E5-B4,"")) | G4: =IF(E4="","",G5+F4) | H4: =IF(E4="","",1-C4/E4)
A5: 46097 | C5: =IF(D5="","",C6+B5) | D5: =IF(E5="","",D6) | E5: =IFERROR(__xludf.DUMMYFUNCTION("FILTER(CUENTAS!AB:AB,A5=CUENTAS!A:A) "),"") | F5: =(IF(E5<>0,E5-E6-B5,"")) | G5: =IF(E5="","",G6+F5) | H5: =IF(E5="","",1-C5/E5)
A6: 46096 | C6: =IF(D6="","",C7+B6) | D6: =IF(E6="","",D7) | E6: =IFERROR(__xludf.DUMMYFUNCTION("FILTER(CUENTAS!AB:AB,A6=CUENTAS!A:A) "),"") | F6: =(IF(E6<>0,E6-E7-B6,"")) | G6: =IF(E6="","",G7+F6) | H6: =IF(E6="","",1-C6/E6)
A7: 46095 | C7: =IF(D7="","",C8+B7) | D7: =IF(E7="","",D8) | E7: =IFERROR(__xludf.DUMMYFUNCTION("FILTER(CUENTAS!AB:AB,A7=CUENTAS!A:A) "),"") | F7: =(IF(E7<>0,E7-E8-B7,"")) | G7: =IF(E7="","",G8+F7) | H7: =IF(E7="","",1-C7/E7)
A8: 46094 | C8: =IF(D8="","",C9+B8) | D8: =IF(E8="","",D9) | E8: =IFERROR(__xludf.DUMMYFUNCTION("FILTER(CUENTAS!AB:AB,A8=CUENTAS!A:A) "),"") | F8: =(IF(E8<>0,E8-E9-B8,"")) | G8: =IF(E8="","",G9+F8) | H8: =IF(E8="","",1-C8/E8)
A9: 46093 | C9: =IF(D9="","",C10+B9) | D9: =IF(E9="","",D10) | E9: =IFERROR(__xludf.DUMMYFUNCTION("FILTER(CUENTAS!AB:AB,A9=CUENTAS!A:A) "),"") | F9: =(IF(E9<>0,E9-E10-B9,"")) | G9: =IF(E9="","",G10+F9) | H9: =IF(E9="","",1-C9/E9)
A10: 46092 | C10: =IF(D10="","",C11+B10) | D10: =IF(E10="","",D11) | E10: =IFERROR(__xludf.DUMMYFUNCTION("FILTER(CUENTAS!AB:AB,A10=CUENTAS!A:A) "),"") | F10: =(IF(E10<>0,E10-E11-B10,"")) | G10: =IF(E10="","",G11+F10) | H10: =IF(E10="","",1-C10/E10)
A11: 46091 | C11: =IF(D11="","",C12+B11) | D11: =IF(E11="","",D12) | E11: =IFERROR(__xludf.DUMMYFUNCTION("FILTER(CUENTAS!AB:AB,A11=CUENTAS!A:A) "),"") | F11: =(IF(E11<>0,E11-E12-B11,"")) | G11: =IF(E11="","",G12+F11) | H11: =IF(E11="","",1-C11/E11)
A12: 46090 | C12: =IF(D12="","",C13+B12) | D12: =IF(E12="","",D13) | E12: =IFERROR(__xludf.DUMMYFUNCTION("FILTER(CUENTAS!AB:AB,A12=CUENTAS!A:A) "),"") | F12: =(IF(E12<>0,E12-E13-B12,"")) | G12: =IF(E12="","",G13+F12) | H12: =IF(E12="","",1-C12/E12)
A13: 46089 | B13: 2122000 | C13: =IF(D13="","",C14+B13) -> 26552325 | D13: =IF(E13="","",D14)+102.687666 -> 1391.1308 | E13: =IFERROR(__xludf.DUMMYFUNCTION("FILTER(CUENTAS!AB:AB,A13=CUENTAS!A:A) "),2.8747167022311553E7) -> 28747167 | F13: =(IF(E13<>0,E13-E14-B13,"")) -> 3707.2705 | G13: =IF(E13="","",G14+F13) -> 2272325 | H13: =IF(E13="","",1-C13/E13) -> 0.076349852
A14: 46088 | C14: =IF(D14="","",C15+B14) -> 24430325 | D14: =IF(E14="","",D15) -> 1288.4431 | E14: =IFERROR(__xludf.DUMMYFUNCTION("FILTER(CUENTAS!AB:AB,A14=CUENTAS!A:A) "),2.6621459751843043E7) -> 26621460 | F14: =(IF(E14<>0,E14-E15-B14,"")) -> 5061.1229 | G14: =IF(E14="","",G15+F14) -> 2268617.7 | H14: =IF(E14="","",1-C14/E14) -> 0.082307083
A15: 46087 | C15: =IF(D15="","",C16+B15) -> 24430325 | D15: =IF(E15="","",D16) -> 1288.4431 | E15: =IFERROR(__xludf.DUMMYFUNCTION("FILTER(CUENTAS!AB:AB,A15=CUENTAS!A:A) "),2.661639862891269E7) -> 26616399 | F15: =(IF(E15<>0,E15-E16-B15,"")) -> -62284.025 | G15: =IF(E15="","",G16+F15) -> 2263556.6 | H15: =IF(E15="","",1-C15/E15) -> 0.082132583
A16: 46086 | C16: =IF(D16="","",C17+B16) -> 24430325 | D16: =IF(E16="","",D17) -> 1288.4431 | E16: =IFERROR(__xludf.DUMMYFUNCTION("FILTER(CUENTAS!AB:AB,A16=CUENTAS!A:A) "),2.6678682653491E7) -> 26678683 | F16: =(IF(E16<>0,E16-E17-B16,"")) -> -6089.1721 | G16: =IF(E16="","",G17+F16) -> 2325840.6 | H16: =IF(E16="","",1-C16/E16) -> 0.084275435
A17: 46085 | C17: =IF(D17="","",C18+B17) -> 24430325 | D17: =IF(E17="","",D18) -> 1288.4431 | E17: =IFERROR(__xludf.DUMMYFUNCTION("FILTER(CUENTAS!AB:AB,A17=CUENTAS!A:A) "),2.6684771825548477E7) -> 26684772 | F17: =(IF(E17<>0,E17-E18-B17,"")) -> -3934.3195 | G17: =IF(E17="","",G18+F17) -> 2331929.8 | H17: =IF(E17="","",1-C17/E17) -> 0.084484394
A18: 46084 | B18: =50000+60000 -> 110000 | C18: =IF(D18="","",C19+B18) -> 24430325 | D18: =IF(E18="","",D19)+2.413836+2.896603 -> 1288.4431 | E18: =IFERROR(__xludf.DUMMYFUNCTION("FILTER(CUENTAS!AB:AB,A18=CUENTAS!A:A) "),2.6688706145055633E7) -> 26688706 | F18: =(IF(E18<>0,E18-E19-B18,"")) -> -35866.467 | G18: =IF(E18="","",G19+F18) -> 2335864.1 | H18: =IF(E18="","",1-C18/E18) -> 0.084619354
A19: 46083 | C19: =IF(D19="","",C20+B19) -> 24320325 | D19: =IF(E19="","",D20) -> 1283.1327 | E19: =IFERROR(__xludf.DUMMYFUNCTION("FILTER(CUENTAS!AB:AB,A19=CUENTAS!A:A) "),2.6614572611982983E7) -> 26614573 | F19: =(IF(E19<>0,E19-E20-B19,"")) -> -567681.61 | G19: =IF(E19="","",G20+F19) -> 2371730.5 | H19: =IF(E19="","",1-C19/E19) -> 0.086202682
A20: 46082 | C20: =IF(D20="","",C21+B20) -> 24320325 | D20: =IF(E20="","",D21) -> 1283.1327 | E20: =IFERROR(__xludf.DUMMYFUNCTION("FILTER(CUENTAS!AB:AB,A20=CUENTAS!A:A) "),2.718225422630104E7) -> 27182254 | F20: =(IF(E20<>0,E20-E21-B20,"")) -> -10341.762 | G20: =IF(E20="","",G21+F20) -> 2939412.2 | H20: =IF(E20="","",1-C20/E20) -> 0.10528667
A21: 46081 | C21: =IF(D21="","",C22+B21) -> 24320325 | D21: =IF(E21="","",D22) -> 1283.1327 | E21: =IFERROR(__xludf.DUMMYFUNCTION("FILTER(CUENTAS!AB:AB,A21=CUENTAS!A:A) "),2.719259598798034E7) -> 27192596 | F21: =(IF(E21<>0,E21-E22-B21,"")) -> -10341.909 | G21: =IF(E21="","",G22+F21) -> 2949753.9 | H21: =IF(E21="","",1-C21/E21) -> 0.10562695
A22: 46080 | C22: =IF(D22="","",C23+B22) -> 24320325 | D22: =IF(E22="","",D23) -> 1283.1327 | E22: =IFERROR(__xludf.DUMMYFUNCTION("FILTER(CUENTAS!AB:AB,A22=CUENTAS!A:A) "),2.7202937896991413E7) -> 27202938 | F22: =(IF(E22<>0,E22-E23-B22,"")) -> -383792.06 | G22: =IF(E22="","",G23+F22) -> 2960095.8 | H22: =IF(E22="","",1-C22/E22) -> 0.10596697
A23: 46079 | C23: =IF(D23="","",C24+B23) -> 24320325 | D23: =IF(E23="","",D24) -> 1283.1327 | E23: =IFERROR(__xludf.DUMMYFUNCTION("FILTER(CUENTAS!AB:AB,A23=CUENTAS!A:A) "),2.7586729953304805E7) -> 27586730 | F23: =(IF(E23<>0,E23-E24-B23,"")) -> -464122.2 | G23: =IF(E23="","",G24+F23) -> 3343887.9 | H23: =IF(E23="","",1-C23/E23) -> 0.11840493
A24: 46078 | C24: =IF(D24="","",C25+B24) -> 24320325 | D24: =IF(E24="","",D25) -> 1283.1327 | E24: =IFERROR(__xludf.DUMMYFUNCTION("FILTER(CUENTAS!AB:AB,A24=CUENTAS!A:A) "),2.8050852156891055E7) -> 28050852 | F24: =(IF(E24<>0,E24-E25-B24,"")) -> 1367.6492 | G24: =IF(E24="","",G25+F24) -> 3808010.1 | H24: =IF(E24="","",1-C24/E24) -> 0.13299158
A25: 46077 | C25: =IF(D25="","",C26+B25) -> 24320325 | D25: =IF(E25="","",D26) -> 1283.1327 | E25: =IFERROR(__xludf.DUMMYFUNCTION("FILTER(CUENTAS!AB:AB,A25=CUENTAS!A:A) "),2.804948450772072E7) -> 28049485 | F25: =(IF(E25<>0,E25-E26-B25,"")) -> 56391.338 | G25: =IF(E25="","",G26+F25) -> 3806642.4 | H25: =IF(E25="","",1-C25/E25) -> 0.1329493
A26: 46076 | C26: =IF(D26="","",C27+B26) -> 24320325 | D26: =IF(E26="","",D27) -> 1283.1327 | E26: =IFERROR(__xludf.DUMMYFUNCTION("FILTER(CUENTAS!AB:AB,A26=CUENTAS!A:A) "),2.799309317022235E7) -> 27993093 | F26: =(IF(E26<>0,E26-E27-B26,"")) -> -186243.93 | G26: =IF(E26="","",G27+F26) -> 3750251.1 | H26: =IF(E26="","",1-C26/E26) -> 0.13120265
A27: 46075 | C27: =IF(D27="","",C28+B27) -> 24320325 | D27: =IF(E27="","",D28) -> 1283.1327 | E27: =IFERROR(__xludf.DUMMYFUNCTION("FILTER(CUENTAS!AB:AB,A27=CUENTAS!A:A) "),2.8179337103580892E7) -> 28179337 | F27: =(IF(E27<>0,E27-E28-B27,"")) -> -4939.0838 | G27: =IF(E27="","",G28+F27) -> 3936495 | H27: =IF(E27="","",1-C27/E27) -> 0.13694474
A28: 46074 | C28: =IF(D28="","",C29+B28) -> 24320325 | D28: =IF(E28="","",D29) -> 1283.1327 | E28: =IFERROR(__xludf.DUMMYFUNCTION("FILTER(CUENTAS!AB:AB,A28=CUENTAS!A:A) "),2.818427618742424E7) -> 28184276 | F28: =(IF(E28<>0,E28-E29-B28,"")) -> -4939.2343 | G28: =IF(E28="","",G29+F28) -> 3941434.1 | H28: =IF(E28="","",1-C28/E28) -> 0.13709599
A29: 46073 | C29: =IF(D29="","",C30+B29) -> 24320325 | D29: =IF(E29="","",D30) -> 1283.1327 | E29: =IFERROR(__xludf.DUMMYFUNCTION("FILTER(CUENTAS!AB:AB,A29=CUENTAS!A:A) "),2.81892154217223E7) -> 28189215 | F29: =(IF(E29<>0,E29-E30-B29,"")) -> 180220.62 | G29: =IF(E29="","",G30+F29) -> 3946373.4 | H29: =IF(E29="","",1-C29/E29) -> 0.13724718
A30: 46072 | C30: =IF(D30="","",C31+B30) -> 24320325 | D30: =IF(E30="","",D31) -> 1283.1327 | E30: =IFERROR(__xludf.DUMMYFUNCTION("FILTER(CUENTAS!AB:AB,A30=CUENTAS!A:A) "),2.8008994806445E7) -> 28008995 | F30: =(IF(E30<>0,E30-E31-B30,"")) -> 194640.46 | G30: =IF(E30="","",G31+F30) -> 3766152.7 | H30: =IF(E30="","",1-C30/E30) -> 0.1316959
A31: 46071 | C31: =IF(D31="","",C32+B31) -> 24320325 | D31: =IF(E31="","",D32) -> 1283.1327 | E31: =IFERROR(__xludf.DUMMYFUNCTION("FILTER(CUENTAS!AB:AB,A31=CUENTAS!A:A) "),2.781435434156225E7) -> 27814354 | F31: =(IF(E31<>0,E31-E32-B31,"")) -> 83900.315 | G31: =IF(E31="","",G32+F31) -> 3571512.3 | H31: =IF(E31="","",1-C31/E31) -> 0.12561964
A32: 46070 | B32: 90000 | C32: =IF(D32="","",C33+B32) -> 24320325 | D32: =IF(E32="","",D33)+4.164445 -> 1283.1327 | E32: =IFERROR(__xludf.DUMMYFUNCTION("FILTER(CUENTAS!AB:AB,A32=CUENTAS!A:A) "),2.773045402704398E7) -> 27730454 | F32: =(IF(E32<>0,E32-E33-B32,"")) -> 6160.1642 | G32: =IF(E32="","",G33+F32) -> 3487612 | H32: =IF(E32="","",1-C32/E32) -> 0.12297415
A33: 46069 | B33: 250000 | C33: =IF(D33="","",C34+B33) -> 24230325 | D33: =IF(E33="","",D34)+11.57048 -> 1278.9682 | E33: =IFERROR(__xludf.DUMMYFUNCTION("FILTER(CUENTAS!AB:AB,A33=CUENTAS!A:A) "),2.7634293862860125E7) -> 27634294 | F33: =(IF(E33<>0,E33-E34-B33,"")) -> -91959.986 | G33: =IF(E33="","",G34+F33) -> 3481451.8 | H33: =IF(E33="","",1-C33/E33) -> 0.12317915
A34: 46068 | B34: =104250-203044.2209+11687+73044 -> -14063.221 | C34: =IF(D34="","",C35+B34) -> 23980325 | D34: =IF(E34="","",D35)+4.808742-9.36583+0.539086 -> 1267.3977 | E34: =IFERROR(__xludf.DUMMYFUNCTION("FILTER(CUENTAS!AB:AB,A34=CUENTAS!A:A) "),2.7476253848980635E7) -> 27476254 | F34: =(IF(E34<>0,E34-E35-B34,""))+73044 -> -6339.9155 | G34: =IF(E34="","",G35+F34) -> 3573411.8 | H34: =IF(E34="","",1-C34/E34) -> 0.12723455
A35: 46067 | C35: =IF(D35="","",C36+B35) -> 23994388 | D35: =IF(E35="","",D36) -> 1271.4157 | E35: =IFERROR(__xludf.DUMMYFUNCTION("FILTER(CUENTAS!AB:AB,A35=CUENTAS!A:A) "),2.756970098537543E7) -> 27569701 | F35: =(IF(E35<>0,E35-E36-B35,"")) -> 361052.71 | G35: =IF(E35="","",G36+F35) -> 3579751.7 | H35: =IF(E35="","",1-C35/E35) -> 0.12968268
A36: 46066 | C36: =IF(D36="","",C37+B36) -> 23994388 | D36: =IF(E36="","",D37) -> 1271.4157 | E36: =IFERROR(__xludf.DUMMYFUNCTION("FILTER(CUENTAS!AB:AB,A36=CUENTAS!A:A) "),2.720864827201448E7) -> 27208648 | F36: =(IF(E36<>0,E36-E37-B36,"")) -> 138559.56 | G36: =IF(E36="","",G37+F36) -> 3218699 | H36: =IF(E36="","",1-C36/E36) -> 0.11813376
A37: 46065 | C37: =IF(D37="","",C38+B37) -> 23994388 | D37: =IF(E37="","",D38) -> 1271.4157 | E37: =IFERROR(__xludf.DUMMYFUNCTION("FILTER(CUENTAS!AB:AB,A37=CUENTAS!A:A) "),2.7070088708867736E7) -> 27070089 | F37: =(IF(E37<>0,E37-E38-B37,"")) -> -189680.59 | G37: =IF(E37="","",G38+F37) -> 3080139.4 | H37: =IF(E37="","",1-C37/E37) -> 0.11361989
A38: 46064 | C38: =IF(D38="","",C39+B38) -> 23994388 | D38: =IF(E38="","",D39) -> 1271.4157 | E38: =IFERROR(__xludf.DUMMYFUNCTION("FILTER(CUENTAS!AB:AB,A38=CUENTAS!A:A) "),2.725976929590516E7) -> 27259769 | F38: =(IF(E38<>0,E38-E39-B38,"")) -> -255520.74 | G38: =IF(E38="","",G39+F38) -> 3269820 | H38: =IF(E38="","",1-C38/E38) -> 0.11978755
A39: 46063 | C39: =IF(D39="","",C40+B39) -> 23994388 | D39: =IF(E39="","",D40) -> 1271.4157 | E39: =IFERROR(__xludf.DUMMYFUNCTION("FILTER(CUENTAS!AB:AB,A39=CUENTAS!A:A) "),2.7515290033096723E7) -> 27515290 | F39: =(IF(E39<>0,E39-E40-B39,"")) -> 10579.113 | G39: =IF(E39="","",G40+F39) -> 3525340.8 | H39: =IF(E39="","",1-C39/E39) -> 0.12796164
A40: 46062 | C40: =IF(D40="","",C41+B40) -> 23994388 | D40: =IF(E40="","",D41) -> 1271.4157 | E40: =IFERROR(__xludf.DUMMYFUNCTION("FILTER(CUENTAS!AB:AB,A40=CUENTAS!A:A) "),2.7504710920412406E7) -> 27504711 | F40: =(IF(E40<>0,E40-E41-B40,"")) -> 140518.96 | G40: =IF(E40="","",G41+F40) -> 3514761.6 | H40: =IF(E40="","",1-C40/E40) -> 0.12762623
...

Sheet GRAFICO
A1: FECHA | B1: valor unidad | C1: promedio | D1: desviacion de la media | E1: Pronóstico | F1: inferior | G1: EMA-50 | H1: EMA-15 | I1: EMA-5 | J1: superior | K1: variación % diaria | L1: desviación estandar | M1: desviacion anualizada | N1: var historica | O1: var(30d) | P1: MDD
A2: 46098 | B2: =IF(DATOS!E4<>"",DATOS!E4/DATOS!D4,"") | C2: =IF(B2<>"", AVERAGE($B2:B$826),"") | D2: =IF(B2<>"",B2-C2,"") | E2: =IF(B2<>"",TREND($B2:$B$751,$A2:$A$751,A2),"") | F2: =IF(B2<>"",H2 - 2.6*STDEV(B2:B16),"") | G2: =IF(B2<>"",(B2-G3)*2/51+G3,"") | H2: =IF(B2<>"",(B2-H3)*0.125+H3,"") | I2: =IF(B2<>"",(B2-I3)*1/3+I3,"") | J2: =IF(B2<>"",H2 + 2.6*STDEV(B2:B16),"") | K2: =IF(B2<>"",ln(B2)-ln(B3),"") | L2: =IF(B2<>"",SQRT(_xlfn.VAR.S($K2:K$750)),"") | M2: =IF(B2<>"",L2*SQRT(365),"") | N2: =IF(B2<>"",PERCENTILE($K2:K$750,0.05),"") | O2: =IF(B2<>"",PERCENTILE(K2:K31,0.05),"") | P2: =IF(B2<>"",B2/MAX($B2:B$826)-1,"")
A3: 46097 | B3: =IF(DATOS!E5<>"",DATOS!E5/DATOS!D5,"") | C3: =IF(B3<>"", AVERAGE($B3:B$826),"") | D3: =IF(B3<>"",B3-C3,"") | E3: =IF(B3<>"",TREND($B3:$B$751,$A3:$A$751,A3),"") | F3: =IF(B3<>"",H3 - 2.6*STDEV(B3:B17),"") | G3: =IF(B3<>"",(B3-G4)*2/51+G4,"") | H3: =IF(B3<>"",(B3-H4)*0.125+H4,"") | I3: =IF(B3<>"",(B3-I4)*1/3+I4,"") | J3: =IF(B3<>"",H3 + 2.6*STDEV(B3:B17),"") | K3: =IF(B3<>"",ln(B3)-ln(B4),"") | L3: =IF(B3<>"",SQRT(_xlfn.VAR.S($K3:K$750)),"") | M3: =IF(B3<>"",L3*SQRT(365),"") | N3: =IF(B3<>"",PERCENTILE($K3:K$750,0.05),"") | O3: =IF(B3<>"",PERCENTILE(K3:K32,0.05),"") | P3: =IF(B3<>"",B3/MAX($B3:B$826)-1,"")
A4: 46096 | B4: =IF(DATOS!E6<>"",DATOS!E6/DATOS!D6,"") | C4: =IF(B4<>"", AVERAGE($B4:B$826),"") | D4: =IF(B4<>"",B4-C4,"") | E4: =IF(B4<>"",TREND($B4:$B$751,$A4:$A$751,A4),"") | F4: =IF(B4<>"",H4 - 2.6*STDEV(B4:B18),"") | G4: =IF(B4<>"",(B4-G5)*2/51+G5,"") | H4: =IF(B4<>"",(B4-H5)*0.125+H5,"") | I4: =IF(B4<>"",(B4-I5)*1/3+I5,"") | J4: =IF(B4<>"",H4 + 2.6*STDEV(B4:B18),"") | K4: =IF(B4<>"",ln(B4)-ln(B5),"") | L4: =IF(B4<>"",SQRT(_xlfn.VAR.S($K4:K$750)),"") | M4: =IF(B4<>"",L4*SQRT(365),"") | N4: =IF(B4<>"",PERCENTILE($K4:K$750,0.05),"") | O4: =IF(B4<>"",PERCENTILE(K4:K33,0.05),"") | P4: =IF(B4<>"",B4/MAX($B4:B$826)-1,"")
A5: 46095 | B5: =IF(DATOS!E7<>"",DATOS!E7/DATOS!D7,"") | C5: =IF(B5<>"", AVERAGE($B5:B$826),"") | D5: =IF(B5<>"",B5-C5,"") | E5: =IF(B5<>"",TREND($B5:$B$751,$A5:$A$751,A5),"") | F5: =IF(B5<>"",H5 - 2.6*STDEV(B5:B19),"") | G5: =IF(B5<>"",(B5-G6)*2/51+G6,"") | H5: =IF(B5<>"",(B5-H6)*0.125+H6,"") | I5: =IF(B5<>"",(B5-I6)*1/3+I6,"") | J5: =IF(B5<>"",H5 + 2.6*STDEV(B5:B19),"") | K5: =IF(B5<>"",ln(B5)-ln(B6),"") | L5: =IF(B5<>"",SQRT(_xlfn.VAR.S($K5:K$750)),"") | M5: =IF(B5<>"",L5*SQRT(365),"") | N5: =IF(B5<>"",PERCENTILE($K5:K$750,0.05),"") | O5: =IF(B5<>"",PERCENTILE(K5:K34,0.05),"") | P5: =IF(B5<>"",B5/MAX($B5:B$826)-1,"")
A6: 46094 | B6: =IF(DATOS!E8<>"",DATOS!E8/DATOS!D8,"") | C6: =IF(B6<>"", AVERAGE($B6:B$826),"") | D6: =IF(B6<>"",B6-C6,"") | E6: =IF(B6<>"",TREND($B6:$B$751,$A6:$A$751,A6),"") | F6: =IF(B6<>"",H6 - 2.6*STDEV(B6:B20),"") | G6: =IF(B6<>"",(B6-G7)*2/51+G7,"") | H6: =IF(B6<>"",(B6-H7)*0.125+H7,"") | I6: =IF(B6<>"",(B6-I7)*1/3+I7,"") | J6: =IF(B6<>"",H6 + 2.6*STDEV(B6:B20),"") | K6: =IF(B6<>"",ln(B6)-ln(B7),"") | L6: =IF(B6<>"",SQRT(_xlfn.VAR.S($K6:K$750)),"") | M6: =IF(B6<>"",L6*SQRT(365),"") | N6: =IF(B6<>"",PERCENTILE($K6:K$750,0.05),"") | O6: =IF(B6<>"",PERCENTILE(K6:K35,0.05),"") | P6: =IF(B6<>"",B6/MAX($B6:B$826)-1,"")
A7: 46093 | B7: =IF(DATOS!E9<>"",DATOS!E9/DATOS!D9,"") | C7: =IF(B7<>"", AVERAGE($B7:B$826),"") | D7: =IF(B7<>"",B7-C7,"") | E7: =IF(B7<>"",TREND($B7:$B$751,$A7:$A$751,A7),"") | F7: =IF(B7<>"",H7 - 2.6*STDEV(B7:B21),"") | G7: =IF(B7<>"",(B7-G8)*2/51+G8,"") | H7: =IF(B7<>"",(B7-H8)*0.125+H8,"") | I7: =IF(B7<>"",(B7-I8)*1/3+I8,"") | J7: =IF(B7<>"",H7 + 2.6*STDEV(B7:B21),"") | K7: =IF(B7<>"",ln(B7)-ln(B8),"") | L7: =IF(B7<>"",SQRT(_xlfn.VAR.S($K7:K$750)),"") | M7: =IF(B7<>"",L7*SQRT(365),"") | N7: =IF(B7<>"",PERCENTILE($K7:K$750,0.05),"") | O7: =IF(B7<>"",PERCENTILE(K7:K36,0.05),"") | P7: =IF(B7<>"",B7/MAX($B7:B$826)-1,"")
A8: 46092 | B8: =IF(DATOS!E10<>"",DATOS!E10/DATOS!D10,"") | C8: =IF(B8<>"", AVERAGE($B8:B$826),"") | D8: =IF(B8<>"",B8-C8,"") | E8: =IF(B8<>"",TREND($B8:$B$751,$A8:$A$751,A8),"") | F8: =IF(B8<>"",H8 - 2.6*STDEV(B8:B22),"") | G8: =IF(B8<>"",(B8-G9)*2/51+G9,"") | H8: =IF(B8<>"",(B8-H9)*0.125+H9,"") | I8: =IF(B8<>"",(B8-I9)*1/3+I9,"") | J8: =IF(B8<>"",H8 + 2.6*STDEV(B8:B22),"") | K8: =IF(B8<>"",ln(B8)-ln(B9),"") | L8: =IF(B8<>"",SQRT(_xlfn.VAR.S($K8:K$750)),"") | M8: =IF(B8<>"",L8*SQRT(365),"") | N8: =IF(B8<>"",PERCENTILE($K8:K$750,0.05),"") | O8: =IF(B8<>"",PERCENTILE(K8:K37,0.05),"") | P8: =IF(B8<>"",B8/MAX($B8:B$826)-1,"")
A9: 46091 | B9: =IF(DATOS!E11<>"",DATOS!E11/DATOS!D11,"") | C9: =IF(B9<>"", AVERAGE($B9:B$826),"") | D9: =IF(B9<>"",B9-C9,"") | E9: =IF(B9<>"",TREND($B9:$B$751,$A9:$A$751,A9),"") | F9: =IF(B9<>"",H9 - 2.6*STDEV(B9:B23),"") | G9: =IF(B9<>"",(B9-G10)*2/51+G10,"") | H9: =IF(B9<>"",(B9-H10)*0.125+H10,"") | I9: =IF(B9<>"",(B9-I10)*1/3+I10,"") | J9: =IF(B9<>"",H9 + 2.6*STDEV(B9:B23),"") | K9: =IF(B9<>"",ln(B9)-ln(B10),"") | L9: =IF(B9<>"",SQRT(_xlfn.VAR.S($K9:K$750)),"") | M9: =IF(B9<>"",L9*SQRT(365),"") | N9: =IF(B9<>"",PERCENTILE($K9:K$750,0.05),"") | O9: =IF(B9<>"",PERCENTILE(K9:K38,0.05),"") | P9: =IF(B9<>"",B9/MAX($B9:B$826)-1,"")
A10: 46090 | B10: =IF(DATOS!E12<>"",DATOS!E12/DATOS!D12,"") | C10: =IF(B10<>"", AVERAGE($B10:B$826),"") | D10: =IF(B10<>"",B10-C10,"") | E10: =IF(B10<>"",TREND($B10:$B$751,$A10:$A$751,A10),"") | F10: =IF(B10<>"",H10 - 2.6*STDEV(B10:B24),"") | G10: =IF(B10<>"",(B10-G11)*2/51+G11,"") | H10: =IF(B10<>"",(B10-H11)*0.125+H11,"") | I10: =IF(B10<>"",(B10-I11)*1/3+I11,"") | J10: =IF(B10<>"",H10 + 2.6*STDEV(B10:B24),"") | K10: =IF(B10<>"",ln(B10)-ln(B11),"") | L10: =IF(B10<>"",SQRT(_xlfn.VAR.S($K10:K$750)),"") | M10: =IF(B10<>"",L10*SQRT(365),"") | N10: =IF(B10<>"",PERCENTILE($K10:K$750,0.05),"") | O10: =IF(B10<>"",PERCENTILE(K10:K39,0.05),"") | P10: =IF(B10<>"",B10/MAX($B10:B$826)-1,"")
A11: 46089 | B11: =IF(DATOS!E13<>"",DATOS!E13/DATOS!D13,"") -> 20664.604 | C11: =IF(B11<>"", AVERAGE($B11:B$826),"") -> 15221.289 | D11: =IF(B11<>"",B11-C11,"") -> 5443.3155 | E11: =IF(B11<>"",TREND($B11:$B$751,$A11:$A$751,A11),"") -> 21485.614 | F11: =IF(B11<>"",H11 - 2.6*STDEV(B11:B25),"") -> 19692.944 | G11: =IF(B11<>"",(B11-G12)*2/51+G12,"") -> 21326.784 | H11: =IF(B11<>"",(B11-H12)*0.125+H12,"") -> 21029.685 | I11: =IF(B11<>"",(B11-I12)*1/3+I12,"") -> 20714.835 | J11: =IF(B11<>"",H11 + 2.6*STDEV(B11:B25),"") -> 22366.425 | K11: =IF(B11<>"",ln(B11)-ln(B12),"") -> 0.0001392489 | L11: =IF(B11<>"",SQRT(_xlfn.VAR.S($K11:K$750)),"") -> 0.008090859 | M11: =IF(B11<>"",L11*SQRT(365),"") -> 0.15457564 | N11: =IF(B11<>"",PERCENTILE($K11:K$750,0.05),"") -> -0.0091653485 | O11: =IF(B11<>"",PERCENTILE(K11:K40,0.05),"") -> -0.01548073 | P11: =IF(B11<>"",B11/MAX($B11:B$826)-1,"") -> -0.064158292
A12: 46088 | B12: =IF(DATOS!E14<>"",DATOS!E14/DATOS!D14,"") -> 20661.727 | C12: =IF(B12<>"", AVERAGE($B12:B$826),"") -> 15214.61 | D12: =IF(B12<>"",B12-C12,"") -> 5447.1171 | E12: =IF(B12<>"",TREND($B12:$B$751,$A12:$A$751,A12),"") -> 21474.495 | F12: =IF(B12<>"",H12 - 2.6*STDEV(B12:B26),"") -> 19694.659 | G12: =IF(B12<>"",(B12-G13)*2/51+G13,"") -> 21353.812 | H12: =IF(B12<>"",(B12-H13)*0.125+H13,"") -> 21081.839 | I12: =IF(B12<>"",(B12-I13)*1/3+I13,"") -> 20739.95 | J12: =IF(B12<>"",H12 + 2.6*STDEV(B12:B26),"") -> 22469.02 | K12: =IF(B12<>"",ln(B12)-ln(B13),"") -> 0.00019013248 | L12: =IF(B12<>"",SQRT(_xlfn.VAR.S($K12:K$750)),"") -> 0.0080962874 | M12: =IF(B12<>"",L12*SQRT(365),"") -> 0.15467935 | N12: =IF(B12<>"",PERCENTILE($K12:K$750,0.05),"") -> -0.0091740085 | O12: =IF(B12<>"",PERCENTILE(K12:K41,0.05),"") -> -0.01548073 | P12: =IF(B12<>"",B12/MAX($B12:B$826)-1,"") -> -0.064288597
A13: 46087 | B13: =IF(DATOS!E15<>"",DATOS!E15/DATOS!D15,"") -> 20657.799 | C13: =IF(B13<>"", AVERAGE($B13:B$826),"") -> 15207.918 | D13: =IF(B13<>"",B13-C13,"") -> 5449.8808 | E13: =IF(B13<>"",TREND($B13:$B$751,$A13:$A$751,A13),"") -> 21463.329 | F13: =IF(B13<>"",H13 - 2.6*STDEV(B13:B27),"") -> 19744.272 | G13: =IF(B13<>"",(B13-G14)*2/51+G14,"") -> 21382.06 | H13: =IF(B13<>"",(B13-H14)*0.125+H14,"") -> 21141.855 | I13: =IF(B13<>"",(B13-I14)*1/3+I14,"") -> 20779.062 | J13: =IF(B13<>"",H13 + 2.6*STDEV(B13:B27),"") -> 22539.438 | K13: =IF(B13<>"",ln(B13)-ln(B14),"") -> -0.0023373284 | L13: =IF(B13<>"",SQRT(_xlfn.VAR.S($K13:K$750)),"") -> 0.0081017332 | M13: =IF(B13<>"",L13*SQRT(365),"") -> 0.1547834 | N13: =IF(B13<>"",PERCENTILE($K13:K$750,0.05),"") -> -0.0091826685 | O13: =IF(B13<>"",PERCENTILE(K13:K42,0.05),"") -> -0.015499362 | P13: =IF(B13<>"",B13/MAX($B13:B$826)-1,"") -> -0.06446649
... A45: 46055 | B45: =IF(DATOS!E47<>"",DATOS!E47/DATOS!D47,"") -> 21736.825 | C45: =IF(B45<>"", AVERAGE($B45:B$826),"") -> 14951.839 | D45: =IF(B45<>"",B45-C45,"") -> 6784.9857 | E45: =IF(B45<>"",TREND($B45:$B$751,$A45:$A$751,A45),"") -> 20920.569 | F45: =IF(B45<>"",H45 - 2.6*STDEV(B45:B59),"") -> 21383.934 | G45: =IF(B45<>"",(B45-G46)*2/51+G46,"") -> 21395.592 | H45: =IF(B45<>"",(B45-H46)*0.125+H46,"") -> 21775.337 | I45: =IF(B45<>"",(B45-I46)*1/3+I46,"") -> 21859.889 | J45: =IF(B45<>"",H45 + 2.6*STDEV(B45:B59),"") -> 22166.74 | K45: =IF(B45<>"",ln(B45)-ln(B46),"") -> -0.0078328208 | L45: =IF(B45<>"",SQRT(_xlfn.VAR.S($K45:K$750)),"") -> 0.0081248338 | M45: =IF(B45<>"",L45*SQRT(365),"") -> 0.15522473 | N45: =IF(B45<>"",PERCENTILE($K45:K$750,0.05),"") -> -0.0088478878 | O45: =IF(B45<>"",PERCENTILE(K45:K74,0.05),"") -> -0.0073503518 | P45: =IF(B45<>"",B45/MAX($B45:B$826)-1,"") -> -0.015600447
A46: 46054 | B46: =IF(DATOS!E48<>"",DATOS!E48/DATOS!D48,"") -> 21907.754 | C46: =IF(B46<>"", AVERAGE($B46:B$826),"") -> 14943.152 | D46: =IF(B46<>"",B46-C46,"") -> 6964.6025 | E46: =IF(B46<>"",TREND($B46:$B$751,$A46:$A$751,A46),"") -> 20900.464 | F46: =IF(B46<>"",H46 - 2.6*STDEV(B46:B60),"") -> 21261.054 | G46: =IF(B46<>"",(B46-G47)*2/51+G47,"") -> 21381.664 | H46: =IF(B46<>"",(B46-H47)*0.125+H47,"") -> 21780.839 | I46: =IF(B46<>"",(B46-I47)*1/3+I47,"") -> 21921.421 | J46: =IF(B46<>"",H46 + 2.6*STDEV(B46:B60),"") -> 22300.623 | K46: =IF(B46<>"",ln(B46)-ln(B47),"") -> -1.5163803e-06 | L46: =IF(B46<>"",SQRT(_xlfn.VAR.S($K46:K$750)),"") -> 0.0081237156 | M46: =IF(B46<>"",L46*SQRT(365),"") -> 0.15520337 | N46: =IF(B46<>"",PERCENTILE($K46:K$750,0.05),"") -> -0.0088501881 | O46: =IF(B46<>"",PERCENTILE(K46:K75,0.05),"") -> -0.00465092 | P46: =IF(B46<>"",B46/MAX($B46:B$826)-1,"") -> -0.0078595442 | U46: =(B46-H46)/STDEV(B46:B60) -> 0.63484102
A47: 46053 | B47: =IF(DATOS!E49<>"",DATOS!E49/DATOS!D49,"") -> 21907.787 | C47: =IF(B47<>"", AVERAGE($B47:B$826),"") -> 14934.223 | D47: =IF(B47<>"",B47-C47,"") -> 6973.5647 | E47: =IF(B47<>"",TREND($B47:$B$751,$A47:$A$751,A47),"") -> 20879.279 | F47: =IF(B47<>"",H47 - 2.6*STDEV(B47:B61),"") -> 21151.239 | G47: =IF(B47<>"",(B47-G48)*2/51+G48,"") -> 21360.191 | H47: =IF(B47<>"",(B47-H48)*0.125+H48,"") -> 21762.708 | I47: =IF(B47<>"",(B47-I48)*1/3+I48,"") -> 21928.255 | J47: =IF(B47<>"",H47 + 2.6*STDEV(B47:B61),"") -> 22374.177 | K47: =IF(B47<>"",ln(B47)-ln(B48),"") -> -0.00095963409 | L47: =IF(B47<>"",SQRT(_xlfn.VAR.S($K47:K$750)),"") -> 0.0081293944 | M47: =IF(B47<>"",L47*SQRT(365),"") -> 0.15531186 | N47: =IF(B47<>"",PERCENTILE($K47:K$750,0.05),"") -> -0.0088524883 | O47: =IF(B47<>"",PERCENTILE(K47:K76,0.05),"") -> -0.00465092 | P47: =IF(B47<>"",B47/MAX($B47:B$826)-1,"") -> -0.0078580398 | U47: =(B47-H47)/STDEV(B47:B61) -> 0.61688694
A48: 46052 | B48: =IF(DATOS!E50<>"",DATOS!E50/DATOS!D50,"") -> 21928.821 | C48: =IF(B48<>"", AVERAGE($B48:B$826),"") -> 14925.271 | D48: =IF(B48<>"",B48-C48,"") -> 7003.5502 | E48: =IF(B48<>"",TREND($B48:$B$751,$A48:$A$751,A48),"") -> 20857.977 | F48: =IF(B48<>"",H48 - 2.6*STDEV(B48:B62),"") -> 21069.68 | G48: =IF(B48<>"",(B48-G49)*2/51+G49,"") -> 21337.84 | H48: =IF(B48<>"",(B48-H49)*0.125+H49,"") -> 21741.982 | I48: =IF(B48<>"",(B48-I49)*1/3+I49,"") -> 21938.489 | J48: =IF(B48<>"",H48 + 2.6*STDEV(B48:B62),"") -> 22414.284 | K48: =IF(B48<>"",ln(B48)-ln(B49),"") -> 0.001203618 | L48: =IF(B48<>"",SQRT(_xlfn.VAR.S($K48:K$750)),"") -> 0.0081348277 | M48: =IF(B48<>"",L48*SQRT(365),"") -> 0.15541566 | N48: =IF(B48<>"",PERCENTILE($K48:K$750,0.05),"") -> -0.0088547886 | O48: =IF(B48<>"",PERCENTILE(K48:K77,0.05),"") -> -0.00465092 | P48: =IF(B48<>"",B48/MAX($B48:B$826)-1,"") -> -0.0069054895 | U48: =(B48-H48)/STDEV(B48:B62) -> 0.72256402
A49: 46051 | B49: =IF(DATOS!E51<>"",DATOS!E51/DATOS!D51,"") -> 21902.443 | C49: =IF(B49<>"", AVERAGE($B49:B$826),"") -> 14916.269 | D49: =IF(B49<>"",B49-C49,"") -> 6986.1741 | E49: =IF(B49<>"",TREND($B49:$B$751,$A49:$A$751,A49),"") -> 20836.439 | F49: =IF(B49<>"",H49 - 2.6*STDEV(B49:B63),"") -> 20931.053 | G49: =IF(B49<>"",(B49-G50)*2/51+G50,"") -> 21313.718 | H49: =IF(B49<>"",(B49-H50)*0.125+H50,"") -> 21715.291 | I49: =IF(B49<>"",(B49-I50)*1/3+I50,"") -> 21943.323 | J49: =IF(B49<>"",H49 + 2.6*STDEV(B49:B63),"") -> 22499.529 | K49: =IF(B49<>"",ln(B49)-ln(B50),"") -> -0.0081330608 | L49: =IF(B49<>"",SQRT(_xlfn.VAR.S($K49:K$750)),"") -> 0.008140626 | M49: =IF(B49<>"",L49*SQRT(365),"") -> 0.15552644 | N49: =IF(B49<>"",PERCENTILE($K49:K$750,0.05),"") -> -0.0088570888 | O49: =IF(B49<>"",PERCENTILE(K49:K78,0.05),"") -> -0.00465092 | P49: =IF(B49<>"",B49/MAX($B49:B$826)-1,"") -> -0.0081000769 | U49: =(B49-H49)/STDEV(B49:B63) -> 0.62046934
A50: 46050 | B50: =IF(DATOS!E52<>"",DATOS!E52/DATOS!D52,"") -> 22081.303 | C50: =IF(B50<>"", AVERAGE($B50:B$826),"") -> 14907.278 | D50: =IF(B50<>"",B50-C50,"") -> 7174.0256 | E50: =IF(B50<>"",TREND($B50:$B$751,$A50:$A$751,A50),"") -> 20814.932 | F50: =IF(B50<>"",H50 - 2.6*STDEV(B50:B64),"") -> 20799.866 | G50: =IF(B50<>"",(B50-G51)*2/51+G51,"") -> 21289.689 | H50: =IF(B50<>"",(B50-H51)*0.125+H51,"") -> 21688.555 | I50: =IF(B50<>"",(B50-I51)*1/3+I51,"") -> 21963.763 | J50: =IF(B50<>"",H50 + 2.6*STDEV(B50:B64),"") -> 22577.243 | K50: =IF(B50<>"",ln(B50)-ln(B51),"") -> 0.0044136461 | L50: =IF(B50<>"",SQRT(_xlfn.VAR.S($K50:K$750)),"") -> 0.008139023 | M50: =IF(B50<>"",L50*SQRT(365),"") -> 0.15549582 | N50: =IF(B50<>"",PERCENTILE($K50:K$750,0.05),"") -> -0.0088593891 | O50: =IF(B50<>"",PERCENTILE(K50:K79,0.05),"") -> -0.00465092 | P50: =IF(B50<>"",B50/MAX($B50:B$826)-1,"") -> 0 | U50: =(B50-H50)/STDEV(B50:B64) -> 1.1490485
A51: 46049 | B51: =IF(DATOS!E53<>"",DATOS!E53/DATOS!D53,"") -> 21984.059 | C51: =IF(B51<>"", AVERAGE($B51:B$826),"") -> 14898.033 | D51: =IF(B51<>"",B51-C51,"") -> 7086.0262 | E51: =IF(B51<>"",TREND($B51:$B$751,$A51:$A$751,A51),"") -> 20792.286 | F51: =IF(B51<>"",H51 - 2.6*STDEV(B51:B65),"") -> 20713.499 | G51: =IF(B51<>"",(B51-G52)*2/51+G52,"") -> 21257.378 | H51: =IF(B51<>"",(B51-H52)*0.125+H52,"") -> 21632.448 | I51: =IF(B51<>"",(B51-I52)*1/3+I52,"") -> 21904.993 | J51: =IF(B51<>"",H51 + 2.6*STDEV(B51:B65),"") -> 22551.397 | K51: =IF(B51<>"",ln(B51)-ln(B52),"") -> -0.00079058421 | L51: =IF(B51<>"",SQRT(_xlfn.VAR.S($K51:K$750)),"") -> 0.0081438582 | M51: =IF(B51<>"",L51*SQRT(365),"") -> 0.15558819 | N51: =IF(B51<>"",PERCENTILE($K51:K$750,0.05),"") -> -0.0088649687 | O51: =IF(B51<>"",PERCENTILE(K51:K80,0.05),"") -> -0.00465092 | P51: =IF(B51<>"",B51/MAX($B51:B$826)-1,"") -> -0.00079027178 | U51: =(B51-H51)/STDEV(B51:B65) -> 0.99481974
A52: 46048 | B52: =IF(DATOS!E54<>"",DATOS!E54/DATOS!D54,"") -> 22001.446 | C52: =IF(B52<>"", AVERAGE($B52:B$826),"") -> 14888.889 | D52: =IF(B52<>"",B52-C52,"") -> 7112.5565 | E52: =IF(B52<>"",TREND($B52:$B$751,$A52:$A$751,A52),"") -> 20770.072 | F52: =IF(B52<>"",H52 - 2.6*STDEV(B52:B66),"") -> 20657.565 | G52: =IF(B52<>"",(B52-G53)*2/51+G53,"") -> 21227.718 | H52: =IF(B52<>"",(B52-H53)*0.125+H53,"") -> 21582.218 | I52: =IF(B52<>"",(B52-I53)*1/3+I53,"") -> 21865.459 | J52: =IF(B52<>"",H52 + 2.6*STDEV(B52:B66),"") -> 22506.87 | K52: =IF(B52<>"",ln(B52)-ln(B53),"") -> 0.0053496081 | L52: =IF(B52<>"",SQRT(_xlfn.VAR.S($K52:K$750)),"") -> 0.0081493874 | M52: =IF(B52<>"",L52*SQRT(365),"") -> 0.15569383 | N52: =IF(B52<>"",PERCENTILE($K52:K$750,0.05),"") -> -0.0088705484 | O52: =IF(B52<>"",PERCENTILE(K52:K81,0.05),"") -> -0.00465092 | P52: =IF(B52<>"",B52/MAX($B52:B$826)-1,"") -> 0 | U52: =(B52-H52)/STDEV(B52:B66) -> 1.1788147
A53: 46047 | B53: =IF(DATOS!E55<>"",DATOS!E55/DATOS!D55,"") -> 21884.061 | C53: =IF(B53<>"", AVERAGE($B53:B$826),"") -> 14879.7 | D53: =IF(B53<>"",B53-C53,"") -> 7004.361 | E53: =IF(B53<>"",TREND($B53:$B$751,$A53:$A$751,A53),"") -> 20747.636 | F53: =IF(B53<>"",H53 - 2.6*STDEV(B53:B67),"") -> 20627.723 | G53: =IF(B53<>"",(B53-G54)*2/51+G54,"") -> 21196.137 | H53: =IF(B53<>"",(B53-H54)*0.125+H54,"") -> 21522.328 | I53: =IF(B53<>"",(B53-I54)*1/3+I54,"") -> 21797.466 | J53: =IF(B53<>"",H53 + 2.6*STDEV(B53:B67),"") -> 22416.933 | K53: =IF(B53<>"",ln(B53)-ln(B54),"") -> 0.00030677002 | L53: =IF(B53<>"",SQRT(_xlfn.VAR.S($K53:K$750)),"") -> 0.0081536146 | M53: =IF(B53<>"",L53*SQRT(365),"") -> 0.15577459 | N53: =IF(B53<>"",PERCENTILE($K53:K$750,0.05),"") -> -0.008876128 | O53: =IF(B53<>"",PERCENTILE(K53:K82,0.05),"") -> -0.00465092 | P53: =IF(B53<>"",B53/MAX($B53:B$826)-1,"") -> 0 | U53: =(B53-H53)/STDEV(B53:B67) -> 1.0513088
A54: 46046 | B54: =IF(DATOS!E56<>"",DATOS!E56/DATOS!D56,"") -> 21877.349 | C54: =IF(B54<>"", AVERAGE($B54:B$826),"") -> 14870.639 | D54: =IF(B54<>"",B54-C54,"") -> 7006.71 | E54: =IF(B54<>"",TREND($B54:$B$751,$A54:$A$751,A54),"") -> 20725.749 | F54: =IF(B54<>"",H54 - 2.6*STDEV(B54:B68),"") -> 20603.327 | G54: =IF(B54<>"",(B54-G55)*2/51+G55,"") -> 21168.058 | H54: =IF(B54<>"",(B54-H55)*0.125+H55,"") -> 21470.652 | I54: =IF(B54<>"",(B54-I55)*1/3+I55,"") -> 21754.169 | J54: =IF(B54<>"",H54 + 2.6*STDEV(B54:B68),"") -> 22337.976 | K54: =IF(B54<>"",ln(B54)-ln(B55),"") -> 0.0001863339 | L54: =IF(B54<>"",SQRT(_xlfn.VAR.S($K54:K$750)),"") -> 0.00815942 | M54: =IF(B54<>"",L54*SQRT(365),"") -> 0.1558855 | N54: =IF(B54<>"",PERCENTILE($K54:K$750,0.05),"") -> -0.0088817077 | O54: =IF(B54<>"",PERCENTILE(K54:K83,0.05),"") -> -0.00465092 | P54: =IF(B54<>"",B54/MAX($B54:B$826)-1,"") -> 0 | U54: =(B54-H54)/STDEV(B54:B68) -> 1.2191658
A55: 46045 | B55: =IF(DATOS!E57<>"",DATOS!E57/DATOS!D57,"") -> 21873.273 | C55: =IF(B55<>"", AVERAGE($B55:B$826),"") -> 14861.563 | D55: =IF(B55<>"",B55-C55,"") -> 7011.7099 | E55: =IF(B55<>"",TREND($B55:$B$751,$A55:$A$751,A55),"") -> 20703.78 | F55: =IF(B55<>"",H55 - 2.6*STDEV(B55:B69),"") -> 20598.716 | G55: =IF(B55<>"",(B55-G56)*2/51+G56,"") -> 21139.108 | H55: =IF(B55<>"",(B55-H56)*0.125+H56,"") -> 21412.552 | I55: =IF(B55<>"",(B55-I56)*1/3+I56,"") -> 21692.579 | J55: =IF(B55<>"",H55 + 2.6*STDEV(B55:B69),"") -> 22226.388 | K55: =IF(B55<>"",ln(B55)-ln(B56),"") -> 0.0068228554 | L55: =IF(B55<>"",SQRT(_xlfn.VAR.S($K55:K$750)),"") -> 0.0081652205 | M55: =IF(B55<>"",L55*SQRT(365),"") -> 0.15599632 | N55: =IF(B55<>"",PERCENTILE($K55:K$750,0.05),"") -> -0.0088872873 | O55: =IF(B55<>"",PERCENTILE(K55:K84,0.05),"") -> -0.00465092 | P55: =IF(B55<>"",B55/MAX($B55:B$826)-1,"") -> 0 | U55: =(B55-H55)/STDEV(B55:B69) -> 1.4718853
A56: 46044 | B56: =IF(DATOS!E58<>"",DATOS!E58/DATOS!D58,"") -> 21724.542 | C56: =IF(B56<>"", AVERAGE($B56:B$826),"") -> 14852.468 | D56: =IF(B56<>"",B56-C56,"") -> 6872.074 | E56: =IF(B56<>"",TREND($B56:$B$751,$A56:$A$751,A56),"") -> 20681.713 | F56: =IF(B56<>"",H56 - 2.6*STDEV(B56:B70),"") -> 20614.105 | G56: =IF(B56<>"",(B56-G57)*2/51+G57,"") -> 21109.142 | H56: =IF(B56<>"",(B56-H57)*0.125+H57,"") -> 21346.735 | I56: =IF(B56<>"",(B56-I57)*1/3+I57,"") -> 21602.232 | J56: =IF(B56<>"",H56 + 2.6*STDEV(B56:B70),"") -> 22079.365 | K56: =IF(B56<>"",ln(B56)-ln(B57),"") -> -0.0017084441 | L56: =IF(B56<>"",SQRT(_xlfn.VAR.S($K56:K$750)),"") -> 0.0081681702 | M56: =IF(B56<>"",L56*SQRT(365),"") -> 0.15605267 | N56: =IF(B56<>"",PERCENTILE($K56:K$750,0.05),"") -> -0.0088928669 | O56: =IF(B56<>"",PERCENTILE(K56:K85,0.05),"") -> -0.00465092 | P56: =IF(B56<>"",B56/MAX($B56:B$826)-1,"") -> -0.0017069855 | U56: =(B56-H56)/STDEV(B56:B70) -> 1.340785
A57: 46043 | B57: =IF(DATOS!E59<>"",DATOS!E59/DATOS!D59,"") -> 21761.689 | C57: =IF(B57<>"", AVERAGE($B57:B$826),"") -> 14843.544 | D57: =IF(B57<>"",B57-C57,"") -> 6918.1456 | E57: =IF(B57<>"",TREND($B57:$B$751,$A57:$A$751,A57),"") -> 20660.379 | F57: =IF(B57<>"",H57 - 2.6*STDEV(B57:B71),"") -> 20620.11 | G57: =IF(B57<>"",(B57-G58)*2/51+G58,"") -> 21084.023 | H57: =IF(B57<>"",(B57-H58)*0.125+H58,"") -> 21292.762 | I57: =IF(B57<>"",(B57-I58)*1/3+I58,"") -> 21541.076 | J57: =IF(B57<>"",H57 + 2.6*STDEV(B57:B71),"") -> 21965.415 | K57: =IF(B57<>"",ln(B57)-ln(B58),"") -> 0.0060034515 | L57: =IF(B57<>"",SQRT(_xlfn.VAR.S($K57:K$750)),"") -> 0.008173387 | M57: =IF(B57<>"",L57*SQRT(365),"") -> 0.15615234 | N57: =IF(B57<>"",PERCENTILE($K57:K$750,0.05),"") -> -0.0088984466 | O57: =IF(B57<>"",PERCENTILE(K57:K86,0.05),"") -> -0.00465092 | P57: =IF(B57<>"",B57/MAX($B57:B$826)-1,"") -> 0 | U57: =(B57-H57)/STDEV(B57:B71) -> 1.8125417
... A94: 46006 | B94: =IF(DATOS!E96<>"",DATOS!E96/DATOS!D96,"") -> 21362.808 | C94: =IF(B94<>"", AVERAGE($B94:B$826),"") -> 14527.831 | D94: =IF(B94<>"",B94-C94,"") -> 6834.9777 | E94: =IF(B94<>"",TREND($B94:$B$751,$A94:$A$751,A94),"") -> 19926.974 | F94: =IF(B94<>"",H94 - 2.6*STDEV(B94:B108),"") -> 20898.462 | G94: =IF(B94<>"",(B94-G95)*2/51+G95,"") -> 20874.37 | H94: =IF(B94<>"",(B94-H95)*0.125+H95,"") -> 21258.11 | I94: =IF(B94<>"",(B94-I95)*1/3+I95,"") -> 21374.336 | J94: =IF(B94<>"",H94 + 2.6*STDEV(B94:B108),"") -> 21617.758 | K94: =IF(B94<>"",ln(B94)-ln(B95),"") -> -0.0031767628 | L94: =IF(B94<>"",SQRT(_xlfn.VAR.S($K94:K$750)),"") -> 0.0082612966 | M94: =IF(B94<>"",L94*SQRT(365),"") -> 0.15783185 | N94: =IF(B94<>"",PERCENTILE($K94:K$750,0.05),"") -> -0.0088817077 | O94: =IF(B94<>"",PERCENTILE(K94:K123,0.05),"") -> -0.0098495926 | P94: =IF(B94<>"",B94/MAX($B94:B$826)-1,"") -> -0.0053365244 | U94: =(B94-H94)/STDEV(B94:B108) -> 0.75689398
A95: 46005 | B95: =DATOS!E97/DATOS!D97 -> 21430.781 | C95: =IF(B95<>"", AVERAGE($B95:B$826),"") -> 14518.493 | D95: =IF(B95<>"",B95-C95,"") -> 6912.2876 | E95: =IF(B95<>"",TREND($B95:$B$751,$A95:$A$751,A95),"") -> 19903.299 | F95: =IF(B95<>"",H95 - 2.6*STDEV(B95:B109),"") -> 20851.863 | G95: =IF(B95<>"",(B95-G96)*2/51+G96,"") -> 20854.433 | H95: =IF(B95<>"",(B95-H96)*0.125+H96,"") -> 21243.153 | I95: =IF(B95<>"",(B95-I96)*1/3+I96,"") -> 21380.1 | J95: =IF(B95<>"",H95 + 2.6*STDEV(B95:B109),"") -> 21634.444 | K95: =IF(B95<>"",ln(B95)-ln(B96),"") -> 0.0001241308 | L95: =IF(B95<>"",SQRT(_xlfn.VAR.S($K95:K$750)),"") -> 0.0082659176 | M95: =IF(B95<>"",L95*SQRT(365),"") -> 0.15792013 | N95: =IF(B95<>"",PERCENTILE($K95:K$750,0.05),"") -> -0.0088872873 | O95: =IF(B95<>"",PERCENTILE(K95:K124,0.05),"") -> -0.0098495926 | P95: =-IF(B95<>"",B95/MAX($B95:B$826)-1,"") -> 0.0021716902 | U95: =(B95-H95)/STDEV(B95:B109) -> 1.2467265
A96: 46004 | B96: =DATOS!E98/DATOS!D98 -> 21428.121 | C96: =AVERAGE($B96:B$826) -> 14509.037 | D96: =B96-C96 -> 6919.0834 | E96: =TREND($B96:$B$751,$A96:$A$751,A96) -> 19879.072 | F96: =IF(B96<>"",H96 - 2.6*STDEV(B96:B110),"") -> 20822.101 | G96: =(B96-G97)*2/51+G97 -> 20830.909 | H96: =(B96-H97)*0.125+H97 -> 21216.349 | I96: =(B96-I97)*1/3+I97 -> 21354.759 | J96: =IF(B96<>"",H96 + 2.6*STDEV(B96:B110),"") -> 21610.598 | K96: =ln(B96)-ln(B97) -> 0.00012414063 | L96: =SQRT(_xlfn.VAR.S($K96:K$750)) -> 0.0082721473 | M96: =L96*SQRT(365) -> 0.15803915 | N96: =PERCENTILE($K96:K$750,0.05) -> -0.0088928669 | O96: =PERCENTILE(K96:K125, 0.05) -> -0.0098495926 | P96: =-IF(B96<>"",B96/MAX($B96:B$826)-1,"") -> 0.0022955437 | U96: =(B96-H96)/STDEV(B96:B110) -> 1.3965971
A97: 46003 | B97: =DATOS!E99/DATOS!D99 -> 21425.461 | C97: =AVERAGE($B97:B$826) -> 14499.559 | D97: =B97-C97 -> 6925.9017 | E97: =TREND($B97:$B$751,$A97:$A$751,A97) -> 19854.72 | F97: =IF(B97<>"",H97 - 2.6*STDEV(B97:B111),"") -> 20803.853 | G97: =(B97-G98)*2/51+G98 -> 20806.533 | H97: =(B97-H98)*0.125+H98 -> 21186.096 | I97: =(B97-I98)*1/3+I98 -> 21318.079 | J97: =IF(B97<>"",H97 + 2.6*STDEV(B97:B111),"") -> 21568.34 | K97: =ln(B97)-ln(B98) -> 0.0013394999 | L97: =SQRT(_xlfn.VAR.S($K97:K$750)) -> 0.0082783912 | M97: =L97*SQRT(365) -> 0.15815844 | N97: =PERCENTILE($K97:K$750,0.05) -> -0.0088984466 | O97: =PERCENTILE(K97:K126, 0.05) -> -0.0098495926 | P97: =-IF(B97<>"",B97/MAX($B97:B$826)-1,"") -> 0.0024193917 | U97: =(B97-H97)/STDEV(B97:B111) -> 1.6281463
A98: 46002 | B98: =DATOS!E100/DATOS!D100 -> 21396.781 | C98: =AVERAGE($B98:B$826) -> 14490.059 | D98: =B98-C98 -> 6906.7221 | E98: =TREND($B98:$B$751,$A98:$A$751,A98) -> 19830.242 | F98: =IF(B98<>"",H98 - 2.6*STDEV(B98:B112),"") -> 20757.821 | G98: =(B98-G99)*2/51+G99 -> 20781.271 | H98: =(B98-H99)*0.125+H99 -> 21151.901 | I98: =(B98-I99)*1/3+I99 -> 21264.388 | J98: =IF(B98<>"",H98 + 2.6*STDEV(B98:B112),"") -> 21545.981 | K98: =ln(B98)-ln(B99) -> 0.0042500602 | L98: =SQRT(_xlfn.VAR.S($K98:K$750)) -> 0.0082847318 | M98: =L98*SQRT(365) -> 0.15827958 | N98: =PERCENTILE($K98:K$750,0.05) -> -0.0089040262 | O98: =PERCENTILE(K98:K127, 0.05) -> -0.0098495926 | P98: =-IF(B98<>"",B98/MAX($B98:B$826)-1,"") -> 0.0037547562 | U98: =(B98-H98)/STDEV(B98:B112) -> 1.6156283
A99: 46001 | B99: =DATOS!E101/DATOS!D101 -> 21306.036 | C99: =AVERAGE($B99:B$826) -> 14480.571 | D99: =B99-C99 -> 6825.4647 | E99: =TREND($B99:$B$751,$A99:$A$751,A99) -> 19805.798 | F99: =IF(B99<>"",H99 - 2.6*STDEV(B99:B113),"") -> 20728.893 | G99: =(B99-G100)*2/51+G100 -> 20756.148 | H99: =(B99-H100)*0.125+H100 -> 21116.919 | I99: =(B99-I100)*1/3+I100 -> 21198.191 | J99: =IF(B99<>"",H99 + 2.6*STDEV(B99:B113),"") -> 21504.944 | K99: =ln(B99)-ln(B100) -> 0.0034573974 | L99: =SQRT(_xlfn.VAR.S($K99:K$750)) -> 0.0082901707 | M99: =L99*SQRT(365) -> 0.15838349 | N99: =PERCENTILE($K99:K$750,0.05) -> -0.0089096059 | O99: =PERCENTILE(K99:K128, 0.05) -> -0.0098495926 | P99: =-IF(B99<>"",B99/MAX($B99:B$826)-1,"") -> 0.0079798737 | U99: =(B99-H99)/STDEV(B99:B113) -> 1.2671997
A100: 46000 | B100: =DATOS!E102/DATOS!D102 -> 21232.5 | C100: =AVERAGE($B100:B$826) -> 14471.183 | D100: =B100-C100 -> 6761.317 | E100: =TREND($B100:$B$751,$A100:$A$751,A100) -> 19781.767 | F100: =IF(B100<>"",H100 - 2.6*STDEV(B100:B114),"") -> 20691.273 | G100: =(B100-G101)*2/51+G101 -> 20733.703 | H100: =(B100-H101)*0.125+H101 -> 21089.902 | I100: =(B100-I101)*1/3+I101 -> 21144.268 | J100: =IF(B100<>"",H100 + 2.6*STDEV(B100:B114),"") -> 21488.53 | K100: =ln(B100)-ln(B101) -> 0.0066011559 | L100: =SQRT(_xlfn.VAR.S($K100:K$750)) -> 0.0082960263 | M100: =L100*SQRT(365) -> 0.15849536 | N100: =PERCENTILE($K100:K$750,0.05) -> -0.0089151855 | O100: =PERCENTILE(K100:K129, 0.05) -> -0.0098495926 | P100: =-IF(B100<>"",B100/MAX($B100:B$826)-1,"") -> 0.011403759 | U100: =(B100-H100)/STDEV(B100:B114) -> 0.93007757
A101: 45999 | B101: =DATOS!E103/DATOS!D103 -> 21092.802 | C101: =AVERAGE($B101:B$826) -> 14461.87 | D101: =B101-C101 -> 6630.9326 | E101: =TREND($B101:$B$751,$A101:$A$751,A101) -> 19758.048 | F101: =IF(B101<>"",H101 - 2.6*STDEV(B101:B115),"") -> 20567.357 | G101: =(B101-G102)*2/51+G102 -> 20713.344 | H101: =(B101-H102)*0.125+H102 -> 21069.531 | I101: =(B101-I102)*1/3+I102 -> 21100.153 | J101: =IF(B101<>"",H101 + 2.6*STDEV(B101:B115),"") -> 21571.704 | K101: =ln(B101)-ln(B102) -> 0.00027456464 | L101: =SQRT(_xlfn.VAR.S($K101:K$750)) -> 0.0082995917 | M101: =L101*SQRT(365) -> 0.15856348 | N101: =PERCENTILE($K101:K$750,0.05) -> -0.0089207652 | O101: =PERCENTILE(K101:K130, 0.05) -> -0.0098495926 | P101: =-IF(B101<>"",B101/MAX($B101:B$826)-1,"") -> 0.017908145 | U101: =(B101-H101)/STDEV(B101:B115) -> 0.12049016
A102: 45998 | B102: =DATOS!E104/DATOS!D104 -> 21087.012 | C102: =AVERAGE($B102:B$826) -> 14452.724 | D102: =B102-C102 -> 6634.2882 | E102: =TREND($B102:$B$751,$A102:$A$751,A102) -> 19735.05 | F102: =IF(B102<>"",H102 - 2.6*STDEV(B102:B116),"") -> 20566.275 | G102: =(B102-G103)*2/51+G103 -> 20697.856 | H102: =(B102-H103)*0.125+H103 -> 21066.206 | I102: =(B102-I103)*1/3+I103 -> 21103.828 | J102: =IF(B102<>"",H102 + 2.6*STDEV(B102:B116),"") -> 21566.137 | K102: =ln(B102)-ln(B103) -> 0.00027463394 | L102: =SQRT(_xlfn.VAR.S($K102:K$750)) -> 0.0083059327 | M102: =L102*SQRT(365) -> 0.15868462 | N102: =PERCENTILE($K102:K$750,0.05) -> -0.0089263448 | O102: =PERCENTILE(K102:K131, 0.05) -> -0.0098495926 | P102: =-IF(B102<>"",B102/MAX($B102:B$826)-1,"") -> 0.018177756 | U102: =(B102-H102)/STDEV(B102:B116) -> 0.10820589
A103: 45997 | B103: =DATOS!E105/DATOS!D105 -> 21081.221 | C103: =AVERAGE($B103:B$826) -> 14443.56 | D103: =B103-C103 -> 6637.6612 | E103: =TREND($B103:$B$751,$A103:$A$751,A103) -> 19711.952 | F103: =IF(B103<>"",H103 - 2.6*STDEV(B103:B117),"") -> 20566.997 | G103: =(B103-G104)*2/51+G104 -> 20681.972 | H103: =(B103-H104)*0.125+H104 -> 21063.234 | I103: =(B103-I104)*1/3+I104 -> 21112.236 | J103: =IF(B103<>"",H103 + 2.6*STDEV(B103:B117),"") -> 21559.47 | K103: =ln(B103)-ln(B104) -> 0.00027470327 | L103: =SQRT(_xlfn.VAR.S($K103:K$750)) -> 0.0083122883 | M103: =L103*SQRT(365) -> 0.15880604 | N103: =PERCENTILE($K103:K$750,0.05) -> -0.0089319244 | O103: =PERCENTILE(K103:K132, 0.05) -> -0.0098495926 | P103: =-IF(B103<>"",B103/MAX($B103:B$826)-1,"") -> 0.018447361 | U103: =(B103-H103)/STDEV(B103:B117) -> 0.094245976
A104: 45996 | B104: =DATOS!E106/DATOS!D106 -> 21075.431 | C104: =AVERAGE($B104:B$826) -> 14434.38 | D104: =B104-C104 -> 6641.0516 | E104: =TREND($B104:$B$751,$A104:$A$751,A104) -> 19688.753 | F104: =IF(B104<>"",H104 - 2.6*STDEV(B104:B118),"") -> 20569.164 | G104: =(B104-G105)*2/51+G105 -> 20665.676 | H104: =(B104-H105)*0.125+H105 -> 21060.664 | I104: =(B104-I105)*1/3+I105 -> 21127.743 | J104: =IF(B104<>"",H104 + 2.6*STDEV(B104:B118),"") -> 21552.164 | K104: =ln(B104)-ln(B105) -> -0.0063202494 | L104: =SQRT(_xlfn.VAR.S($K104:K$750)) -> 0.0083186585 | M104: =L104*SQRT(365) -> 0.15892775 | N104: =PERCENTILE($K104:K$750,0.05) -> -0.0089375041 | O104: =PERCENTILE(K104:K133, 0.05) -> -0.0098495926 | P104: =-IF(B104<>"",B104/MAX($B104:B$826)-1,"") -> 0.018716959 | U104: =(B104-H104)/STDEV(B104:B118) -> 0.078117407
A105: 45995 | B105: =DATOS!E107/DATOS!D107 -> 21209.055 | C105: =AVERAGE($B105:B$826) -> 14425.181 | D105: =B105-C105 -> 6783.8735 | E105: =TREND($B105:$B$751,$A105:$A$751,A105) -> 19665.453 | F105: =IF(B105<>"",H105 - 2.6*STDEV(B105:B119),"") -> 20572.621 | G105: =(B105-G106)*2/51+G106 -> 20648.952 | H105: =(B105-H106)*0.125+H106 -> 21058.554 | I105: =(B105-I106)*1/3+I106 -> 21153.899 | J105: =IF(B105<>"",H105 + 2.6*STDEV(B105:B119),"") -> 21544.488 | K105: =ln(B105)-ln(B106) -> 0.00023026742 | L105: =SQRT(_xlfn.VAR.S($K105:K$750)) -> 0.0083199889 | M105: =L105*SQRT(365) -> 0.15895316 | N105: =PERCENTILE($K105:K$750,0.05) -> -0.0089430837 | O105: =PERCENTILE(K105:K134, 0.05) -> -0.0097339162 | P105: =-IF(B105<>"",B105/MAX($B105:B$826)-1,"") -> 0.012495365 | U105: =(B105-H105)/STDEV(B105:B119) -> 0.80525759
A106: 45994 | B106: =DATOS!E108/DATOS!D108 -> 21204.172 | C106: =AVERAGE($B106:B$826) -> 14415.772 | D106: =B106-C106 -> 6788.3993 | E106: =TREND($B106:$B$751,$A106:$A$751,A106) -> 19641.189 | F106: =IF(B106<>"",H106 - 2.6*STDEV(B106:B120),"") -> 20544.677 | G106: =(B106-G107)*2/51+G107 -> 20626.09 | H106: =(B106-H107)*0.125+H107 -> 21037.054 | I106: =(B106-I107)*1/3+I107 -> 21126.32 | J106: =IF(B106<>"",H106 + 2.6*STDEV(B106:B120),"") -> 21529.432 | K106: =ln(B106)-ln(B107) -> -0.0036003184 | L106: =SQRT(_xlfn.VAR.S($K106:K$750)) -> 0.0083263759 | M106: =L106*SQRT(365) -> 0.15907519 | N106: =PERCENTILE($K106:K$750,0.05) -> -0.0089486634 | O106: =PERCENTILE(K106:K135, 0.05) -> -0.0097339162 | P106: =-IF(B106<>"",B106/MAX($B106:B$826)-1,"") -> 0.012722729 | U106: =(B106-H106)/STDEV(B106:B120) -> 0.88246406
A107: 45993 | B107: =DATOS!E109/DATOS!D109 -> 21280.651 | C107: =AVERAGE($B107:B$826) -> 14406.344 | D107: =B107-C107 -> 6874.307 | E107: =TREND($B107:$B$751,$A107:$A$751,A107) -> 19616.811 | F107: =IF(B107<>"",H107 - 2.6*STDEV(B107:B121),"") -> 20474.273 | G107: =(B107-G108)*2/51+G108 -> 20602.495 | H107: =(B107-H108)*0.125+H108 -> 21013.18 | I107: =(B107-I108)*1/3+I108 -> 21087.394 | J107: =IF(B107<>"",H107 + 2.6*STDEV(B107:B121),"") -> 21552.088 | K107: =ln(B107)-ln(B108) -> 0.0081302169 | L107: =SQRT(_xlfn.VAR.S($K107:K$750)) -> 0.0083307848 | M107: =L107*SQRT(365) -> 0.15915942 | N107: =PERCENTILE($K107:K$750,0.05) -> -0.008954243 | O107: =PERCENTILE(K107:K136, 0.05) -> -0.0097339162 | P107: =-IF(B107<>"",B107/MAX($B107:B$826)-1,"") -> 0.0091618105 | U107: =(B107-H107)/STDEV(B107:B121) -> 1.2904327
...

Sheet BALANCE
B3: DIAS OPERACIÓN | E3: DEPOSITOS
B4: INICIO | C4: 45274 | E4: INVERSIÓN | F4: =DATOS!C2 -> 26552325 | G4: =F4/$F$6 -> 0.78089734
B5: HOY | C5: =TODAY() -> 46090 | E5: APALANCAMIENTO | F5: =-FVA!K25 -> 7450000 | G5: =F5/$F$6 -> 0.21910266
B6: DIAS | C6: =C5-C4 -> 816 | E6: TOTAL DEPOSITO | F6: =SUM(F4:F5) -> 34002325
E7: =F7-F5 -> 515697.52 | F7: =F4*30% -> 7965697.5 | G7: =F7/SUM(F4+F7) -> 0.23076923
B8: VALOR DE LA UNIDAD | E8: VALORIZACIÓN
B9: VU inicial | C9: 10000 | E9: ACTIVO BRUTO | F9: =FVA!P11 -> 37025616
B10: VU actual | C10: =F12/C18 -> 20664.604 | E10: PASIVOS | F10: =CUENTAS!AC2 -> 8273161.2 | G10: =F10/$F$9 -> 0.22344425
B11: VU futuro (1) | E11: GASTOS | F11: =CUENTAS!AD2 -> 5288.0822 | G11: =F11/$F$9 -> 0.00014282226
B12: max. historico | C12: =MAX(GRAFICO!$B:$B) -> 22081.303 | E12: ACTIVO NETO | F12: =F9-F10-abs(F11) -> 28747167 | G12: =F12/$F$9 -> 0.77641292
B13: hoy | C13: =SUMIF(GRAFICO!$A:$A,TODAY(),GRAFICO!$B:$B) -> 0
B14: % distancia | C14: =C13/C12 -> 0 | E14: DISTRIBUCIÓN DE ACTIVOS
E15: Renta fija | F15: =SUM(CUENTAS!S2:Z2) -> 16120098 | G15: =F15/(SUM($F$15:$F$17)) -> 0.43537691
B16: UNIDADES | E16: Renta variable | F16: =SUM(CUENTAS!G2:R2) -> 17029018 | G16: =F16/(SUM($F$15:$F$17)) -> 0.45992531
B17: U creadas | C17: 10000 | E17: Efectivo | F17: =CUENTAS!AA2 -> 3876499.8 | G17: =F17/(SUM($F$15:$F$17)) -> 0.10469778
B18: U circulantes | C18: =DATOS!D2 -> 1391.1308 | E18: Total | F18: =SUM(F15:F17) -> 37025616 | G18: =ROUND(F9,3)=ROUND(F18,3) -> TRUE
B19: U disponibles | C19: =C17-C18 -> 8608.8692
E20: ACTIVOS LÍQUIDOS VS ACTIVOS ILÍQUIDOS
E21: LÍQUIDOS | F21: =F16+F17+SUMIF(FVA!J:J,"Bitcoin",FVA!L:L) -> 20905518 | G21: =F21/SUM($F$21:$F$22) -> 0.56462309
E22: ILÍQUIDOS | F22: =F18-F21 -> 16120098 | G22: =F22/SUM($F$21:$F$22) -> 0.43537691

Sheet CUENTAS
A1: FECHA | B1: DOLAR | C1: BVC | D1: TES | E1: TES2 | F1: MINEROS | G1: ACTIVO 1 | H1: ACTIVO 2 | I1: ACTIVO 3 | J1: ACTIVO 4 | K1: ACTIVO 5 | L1: ACTIVO 6 | M1: ACTIVO 7 | N1: ACTIVO 8 | O1: ACTIVO 9 | P1: ACTIVO 10 | Q1: ACTIVO 11 | R1: ACTIVO 12 | S1: ACTIVO 13 | T1: ACTIVO 14 | U1: ACTIVO 15 | V1: ACTIVO 16 | W1: ACTIVO 17 | X1: ACTIVO 18 | Y1: ACTIVO 19 | Z1: ACTIVO 20 | AA1: CARTERA | AB1: ACTIVOS | AC1: apalancamiento | AD1: gastos | AE1: A BRUTO | AF1: EFC/ACT
A2: =IFERROR(__xludf.DUMMYFUNCTION("MIN(FILTER(ROW($AG$4:$AG1388),MMULT(N(LEN($G$4:$AG1388)>0), TRANSPOSE(COLUMN($G$4:$AG$4)^0)) = COLUMNS($G$4:$AG1388)))"),13.0) -> 13 | B2: =INDIRECT(ADDRESS($A$2, COLUMN())) | C2: =INDIRECT(ADDRESS($A$2, COLUMN())) | D2: =INDIRECT(ADDRESS($A$2, COLUMN())) | E2: =INDIRECT(ADDRESS($A$2, COLUMN())) | F2: =INDIRECT(ADDRESS($A$2, COLUMN())) | G2: =INDIRECT(ADDRESS($A$2, COLUMN())) -> 2604140 | H2: =INDIRECT(ADDRESS($A$2, COLUMN())) -> 2470500 | I2: =INDIRECT(ADDRESS($A$2, COLUMN())) -> 373680 | ... AG2: =INDIRECT(ADDRESS($A$2, COLUMN())) -> 8278449.3
A3: =A2+1 -> 14 | B3: {=(INDIRECT(ADDRESS($A$2, COLUMN()))-INDIRECT(ADDRESS($A$3, COLUMN())))/INDIRECT(ADDRESS($A$3, COLUMN()))} -> #DIV/0! | G3: =(INDIRECT(ADDRESS($A$2, COLUMN()))-INDIRECT(ADDRESS($A$3, COLUMN())))/INDIRECT(ADDRESS($A$3, COLUMN())) -> 0 | H3: =(INDIRECT(ADDRESS($A$2, COLUMN()))-INDIRECT(ADDRESS($A$3, COLUMN())))/INDIRECT(ADDRESS($A$3, COLUMN())) -> 0 | I3: =(INDIRECT(ADDRESS($A$2, COLUMN()))-INDIRECT(ADDRESS($A$3, COLUMN())))/INDIRECT(ADDRESS($A$3, COLUMN())) -> 0 | J3: =(INDIRECT(ADDRESS($A$2, COLUMN()))-INDIRECT(ADDRESS($A$3, COLUMN())))/INDIRECT(ADDRESS($A$3, COLUMN())) -> 0 | K3: =(INDIRECT(ADDRESS($A$2, COLUMN()))-INDIRECT(ADDRESS($A$3, COLUMN())))/INDIRECT(ADDRESS($A$3, COLUMN())) -> #DIV/0! | L3: =(INDIRECT(ADDRESS($A$2, COLUMN()))-INDIRECT(ADDRESS($A$3, COLUMN())))/INDIRECT(ADDRESS($A$3, COLUMN())) -> 0 | M3: =(INDIRECT(ADDRESS($A$2, COLUMN()))-INDIRECT(ADDRESS($A$3, COLUMN())))/INDIRECT(ADDRESS($A$3, COLUMN())) -> 0 | N3: =(INDIRECT(ADDRESS($A$2, COLUMN()))-INDIRECT(ADDRESS($A$3, COLUMN())))/INDIRECT(ADDRESS($A$3, COLUMN())) -> 0 | ... AG3: =(INDIRECT(ADDRESS($A$2, COLUMN()))-INDIRECT(ADDRESS($A$3, COLUMN())))/INDIRECT(ADDRESS($A$3, COLUMN())) -> -0.0040087102
A4: =A5+1 -> 46098
A5: =A6+1 -> 46097
A6: =A7+1 -> 46096
A7: =A8+1 -> 46095
A8: =A9+1 -> 46094
A9: =A10+1 -> 46093
A10: =A11+1 -> 46092
A11: =A12+1 -> 46091 | AB11: =IF((SUM(C11:AA11)-AC11-abs(AD11))<18000000,,SUM(C11:AA11)-AC11-abs(AD11))
A12: =A13+1 -> 46090 | AB12: =IF((SUM(C12:AA12)-AC12-abs(AD12))<18000000,,SUM(C12:AA12)-AC12-abs(AD12))
A13: =A14+1 -> 46089 | G13: =209*12460 -> 2604140 | H13: =45*54900 -> 2470500 | I13: =6*62280 -> 373680 | J13: =80*41600 -> 3328000 | K13: 0 | L13: =2*67500 -> 135000 | M13: =59*16320 -> 962880 | N13: =124*18960 -> 2351040 | O13: =1*814000 -> 814000 | P13: =5*218000 -> 1090000 | Q13: =493*2425 -> 1195525 | R13: =R14 -> 1704253 | S13: =S14+877.8473 -> 578622.2 | T13: =T14+3860+2122000 -> 5071335 | U13: =U14+0 -> 1344990.1 | V13: =V14*1.0002-40000 -> 3649929.6 | W13: =W14+417 -> 1019085 | X13: =X14+1731.342590164 -> 1139540.2 | Y13: =Y14+2155.77 -> 3032988.4 | Z13: =Z14+608 -> 283608 | AA13: =AA14 -> 3876499.8 | AB13: =IF((SUM(C13:AA13)-AC13-abs(AD13))<18000000,,SUM(C13:AA13)-AC13-abs(AD13)) -> 28747167 | AC13: =AC14+1218.527778+1962 -> 8273161.2 | AD13: =AD14+3500-40000 -> 5288.0822 | AE13: =IF(AB13="",,(AB13+AC13+abs(AD13))) -> 37025616 | AF13: =AA13/AB13 -> 0.13484806 | AG13: =AE13-AB13 -> 8278449.3
A14: =A15+1 -> 46088 | G14: =209*12460 -> 2604140 | H14: =45*54900 -> 2470500 | I14: =6*62280 -> 373680 | J14: =80*41600 -> 3328000 | K14: 0 | L14: =2*67500 -> 135000 | M14: =59*16320 -> 962880 | N14: =124*18960 -> 2351040 | O14: =1*814000 -> 814000 | P14: =5*218000 -> 1090000 | Q14: =493*2425 -> 1195525 | R14: =R15 -> 1704253 | S14: =S15+877.8473 -> 577744.36 | T14: =T15+3860 -> 2945475 | U14: =U15+0 -> 1344990.1 | V14: =V15*1.0002 -> 3689191.8 | W14: =W15+417 -> 1018668 | X14: =X15+1731.342590164 -> 1137808.9 | Y14: =Y15+2155.77 -> 3030832.6 | Z14: =283000 -> 283000 | AA14: =AA15+4000000-283000 -> 3876499.8 | AB14: =IF((SUM(C14:AA14)-AC14-abs(AD14))<18000000,,SUM(C14:AA14)-AC14-abs(AD14)) -> 26621460 | AC14: =AC15+1218.527778+4000000 -> 8269980.7 | AD14: =AD15+3500 -> 41788.082 | AE14: =IF(AB14="",,(AB14+AC14+abs(AD14))) -> 34933228 | AF14: =AA14/AB14 -> 0.1456156 | AG14: =AE14-AB14 -> 8311768.7
A15: =A16+1 -> 46087 | G15: =209*12460 -> 2604140 | H15: =45*54900 -> 2470500 | I15: =6*62280 -> 373680 | J15: =80*41600 -> 3328000 | K15: 0 | L15: =2*67500 -> 135000 | M15: =59*16320 -> 962880 | N15: =124*18960 -> 2351040 | O15: =1*814000 -> 814000 | P15: =5*218000 -> 1090000 | Q15: =493*2425 -> 1195525 | R15: =R16 -> 1704253 | S15: =S16+877.8473 -> 576866.51 | T15: =T16+3860 -> 2941615 | U15: =U16+0 -> 1344990.1 | V15: =V16*1.0002 -> 3688454.1 | W15: =W16+417 -> 1018251 | X15: =X16+1731.342590164 -> 1136077.5 | Y15: =Y16+2155.77 -> 3028676.8 | Z15: 0 | AA15: =AA16 -> 159499.8 | AB15: =IF((SUM(C15:AA15)-AC15-abs(AD15))<18000000,,SUM(C15:AA15)-AC15-abs(AD15)) -> 26616399 | AC15: =AC16+1218.527778 -> 4268762.1 | AD15: =AD16+3500 -> 38288.082 | AE15: =IF(AB15="",,(AB15+AC15+abs(AD15))) -> 30923449 | AF15: =AA15/AB15 -> 0.0059925387 | AG15: =AE15-AB15 -> 4307050.2
A16: =A17+1 -> 46086 | G16: =209*12500 -> 2612500 | H16: =45*56000 -> 2520000 | I16: =6*61500 -> 369000 | J16: =80*41500 -> 3320000 | K16: 0 | L16: =2*67700 -> 135400 | M16: =59*16920 -> 998280 | N16: =124*18980 -> 2353520 | O16: =1*825000 -> 825000 | P16: =5*218000 -> 1090000 | Q16: =493*2370 -> 1168410 | R16: =R17 -> 1704253 | S16: =S17+877.8473 -> 575988.66 | T16: =T17+3860 -> 2937755 | U16: =U17+0 -> 1344990.1 | V16: =V17*1.0002 -> 3687716.5 | W16: =W17+417 -> 1017834 | X16: =X17+1731.342590164 -> 1134346.2 | Y16: =Y17+2155.77 -> 3026521.1 | Z16: 0 | AA16: =AA17 -> 159499.8 | AB16: =IF((SUM(C16:AA16)-AC16-abs(AD16))<18000000,,SUM(C16:AA16)-AC16-abs(AD16)) -> 26678683 | AC16: =AC17+1218.527778 -> 4267543.6 | AD16: =AD17+3500 -> 34788.082 | AE16: =IF(AB16="",,(AB16+AC16+abs(AD16))) -> 30981014 | AF16: =AA16/AB16 -> 0.0059785486 | AG16: =AE16-AB16 -> 4302331.7
A17: =A18+1 -> 46085 | G17: =209*12480 -> 2608320 | H17: =45*56660 -> 2549700 | I17: =6*63000 -> 378000 | J17: =80*41520 -> 3321600 | K17: 0 | L17: =2*65260 -> 130520 | M17: =59*17200 -> 1014800 | N17: =124*19420 -> 2408080 | O17: =1*812500 -> 812500 | P17: =5*221000 -> 1105000 | Q17: =493*2180 -> 1074740 | R17: =R18 -> 1704253 | S17: =S18+877.8473 -> 575110.82 | T17: =T18+3860 -> 2933895 | U17: =U18+0 -> 1344990.1 | V17: =V18*1.0002 -> 3686979.2 | W17: =W18+417 -> 1017417 | X17: =X18+1731.342590164 -> 1132614.9 | Y17: =Y18+2155.77 -> 3024365.3 | Z17: 0 | AA17: =AA18 -> 159499.8 | AB17: =IF((SUM(C17:AA17)-AC17-abs(AD17))<18000000,,SUM(C17:AA17)-AC17-abs(AD17)) -> 26684772 | AC17: =AC18+1218.527778 -> 4266325.1 | AD17: =AD18+3500 -> 31288.082 | AE17: =IF(AB17="",,(AB17+AC17+abs(AD17))) -> 30982385 | AF17: =AA17/AB17 -> 0.0059771843 | AG17: =AE17-AB17 -> 4297613.2
